Workbook

Sheet Resumen
A1: Resumen de pruebas: SauceDemo
A2: Esta hoja se calcula sola a partir de las hojas "Casos de prueba", "Requisitos" y "Bugs". No escribas aquí.
A4: Ejecución
A5: Total de casos | B5: =COUNTA('Casos de prueba'!$A$2:$A$500) -> 50
A6: Aprobados | B6: =COUNTIF('Casos de prueba'!$N$2:$N$500,"Aprobado") -> 0
A7: Fallidos | B7: =COUNTIF('Casos de prueba'!$N$2:$N$500,"Fallido") -> 0
A8: Bloqueados | B8: =COUNTIF('Casos de prueba'!$N$2:$N$500,"Bloqueado") -> 0
A9: No ejecutados | B9: =COUNTIF('Casos de prueba'!$N$2:$N$500,"No ejecutado") -> 50
A10: % de ejecución (aprobados + fallidos ÷ total) | B10: =IFERROR((B6+B7)/B5,0) -> 0
A11: % de aprobación (aprobados ÷ ejecutados) | B11: =IFERROR(B6/(B6+B7),0) -> 0
A13: Criterios de salida (plan de pruebas, sección 7) | C13: Estado
A14: Casos de prioridad Alta ejecutados (meta: 100 %) | B14: =IFERROR((COUNTIFS('Casos de prueba'!$J$2:$J$500,"Alta",'Casos de prueba'!$N$2:$N$500,"Aprobado")+COUNTIFS('Casos de prueba'!$J$2:$J$500,"Alta",'Casos de prueba'!$N$2:$N$500,"Fallido"))/COUNTIF('Casos de prueba'!$J$2:$J$500,"Alta"),0) -> 0 | C14: =IF(B14>=1,"Cumple","Pendiente") -> Pendiente
A15: Total de casos ejecutados (meta: 90 % o más) | B15: =B10 -> 0 | C15: =IF(B15>=0.9,"Cumple","Pendiente") -> Pendiente
A17: Cobertura de requisitos
A18: Total de requisitos | B18: =COUNTA(Requisitos!$A$2:$A$18) -> 17
A19: Requisitos cubiertos (con al menos un caso ejecutado) | B19: =COUNTIF(Requisitos!$I$2:$I$18,"Cubierto") -> 0
A20: Requisitos con fallas | B20: =COUNTIF(Requisitos!$J$2:$J$18,"Con fallas") -> 0
A21: % de cobertura de requisitos | B21: =IFERROR(B19/B18,0) -> 0
A23: Por módulo
A24: Módulo | B24: Casos | C24: Ejecutados | D24: Aprobados | E24: Fallidos | F24: Bugs
A25: Login | B25: =COUNTIF('Casos de prueba'!$B$2:$B$500,A25) -> 12 | C25: =COUNTIFS('Casos de prueba'!$B$2:$B$500,A25,'Casos de prueba'!$N$2:$N$500,"Aprobado")+COUNTIFS('Casos de prueba'!$B$2:$B$500,A25,'Casos de prueba'!$N$2:$N$500,"Fallido") -> 0 | D25: =COUNTIFS('Casos de prueba'!$B$2:$B$500,A25,'Casos de prueba'!$N$2:$N$500,"Aprobado") -> 0 | E25: =COUNTIFS('Casos de prueba'!$B$2:$B$500,A25,'Casos de prueba'!$N$2:$N$500,"Fallido") -> 0 | F25: =COUNTIF(Bugs!$C$2:$C$61,A25) -> 0
A26: Catálogo | B26: =COUNTIF('Casos de prueba'!$B$2:$B$500,A26) -> 12 | C26: =COUNTIFS('Casos de prueba'!$B$2:$B$500,A26,'Casos de prueba'!$N$2:$N$500,"Aprobado")+COUNTIFS('Casos de prueba'!$B$2:$B$500,A26,'Casos de prueba'!$N$2:$N$500,"Fallido") -> 0 | D26: =COUNTIFS('Casos de prueba'!$B$2:$B$500,A26,'Casos de prueba'!$N$2:$N$500,"Aprobado") -> 0 | E26: =COUNTIFS('Casos de prueba'!$B$2:$B$500,A26,'Casos de prueba'!$N$2:$N$500,"Fallido") -> 0 | F26: =COUNTIF(Bugs!$C$2:$C$61,A26) -> 0
A27: Detalle | B27: =COUNTIF('Casos de prueba'!$B$2:$B$500,A27) -> 3 | C27: =COUNTIFS('Casos de prueba'!$B$2:$B$500,A27,'Casos de prueba'!$N$2:$N$500,"Aprobado")+COUNTIFS('Casos de prueba'!$B$2:$B$500,A27,'Casos de prueba'!$N$2:$N$500,"Fallido") -> 0 | D27: =COUNTIFS('Casos de prueba'!$B$2:$B$500,A27,'Casos de prueba'!$N$2:$N$500,"Aprobado") -> 0 | E27: =COUNTIFS('Casos de prueba'!$B$2:$B$500,A27,'Casos de prueba'!$N$2:$N$500,"Fallido") -> 0 | F27: =COUNTIF(Bugs!$C$2:$C$61,A27) -> 0
A28: Carrito | B28: =COUNTIF('Casos de prueba'!$B$2:$B$500,A28) -> 3 | C28: =COUNTIFS('Casos de prueba'!$B$2:$B$500,A28,'Casos de prueba'!$N$2:$N$500,"Aprobado")+COUNTIFS('Casos de prueba'!$B$2:$B$500,A28,'Casos de prueba'!$N$2:$N$500,"Fallido") -> 0 | D28: =COUNTIFS('Casos de prueba'!$B$2:$B$500,A28,'Casos de prueba'!$N$2:$N$500,"Aprobado") -> 0 | E28: =COUNTIFS('Casos de prueba'!$B$2:$B$500,A28,'Casos de prueba'!$N$2:$N$500,"Fallido") -> 0 | F28: =COUNTIF(Bugs!$C$2:$C$61,A28) -> 0
A29: Checkout | B29: =COUNTIF('Casos de prueba'!$B$2:$B$500,A29) -> 11 | C29: =COUNTIFS('Casos de prueba'!$B$2:$B$500,A29,'Casos de prueba'!$N$2:$N$500,"Aprobado")+COUNTIFS('Casos de prueba'!$B$2:$B$500,A29,'Casos de prueba'!$N$2:$N$500,"Fallido") -> 0 | D29: =COUNTIFS('Casos de prueba'!$B$2:$B$500,A29,'Casos de prueba'!$N$2:$N$500,"Aprobado") -> 0 | E29: =COUNTIFS('Casos de prueba'!$B$2:$B$500,A29,'Casos de prueba'!$N$2:$N$500,"Fallido") -> 0 | F29: =COUNTIF(Bugs!$C$2:$C$61,A29) -> 0
A30: Menú | B30: =COUNTIF('Casos de prueba'!$B$2:$B$500,A30) -> 4 | C30: =COUNTIFS('Casos de prueba'!$B$2:$B$500,A30,'Casos de prueba'!$N$2:$N$500,"Aprobado")+COUNTIFS('Casos de prueba'!$B$2:$B$500,A30,'Casos de prueba'!$N$2:$N$500,"Fallido") -> 0 | D30: =COUNTIFS('Casos de prueba'!$B$2:$B$500,A30,'Casos de prueba'!$N$2:$N$500,"Aprobado") -> 0 | E30: =COUNTIFS('Casos de prueba'!$B$2:$B$500,A30,'Casos de prueba'!$N$2:$N$500,"Fallido") -> 0 | F30: =COUNTIF(Bugs!$C$2:$C$61,A30) -> 0
A31: Flujo completo | B31: =COUNTIF('Casos de prueba'!$B$2:$B$500,A31) -> 5 | C31: =COUNTIFS('Casos de prueba'!$B$2:$B$500,A31,'Casos de prueba'!$N$2:$N$500,"Aprobado")+COUNTIFS('Casos de prueba'!$B$2:$B$500,A31,'Casos de prueba'!$N$2:$N$500,"Fallido") -> 0 | D31: =COUNTIFS('Casos de prueba'!$B$2:$B$500,A31,'Casos de prueba'!$N$2:$N$500,"Aprobado") -> 0 | E31: =COUNTIFS('Casos de prueba'!$B$2:$B$500,A31,'Casos de prueba'!$N$2:$N$500,"Fallido") -> 0 | F31: =COUNTIF(Bugs!$C$2:$C$61,A31) -> 0
A32: Total | B32: =SUM(B25:B31) -> 50 | C32: =SUM(C25:C31) -> 0 | D32: =SUM(D25:D31) -> 0 | E32: =SUM(E25:E31) -> 0 | F32: =SUM(F25:F31) -> 0
A34: Bugs por severidad
A35: Crítica | B35: =COUNTIF(Bugs!$F$2:$F$61,"Crítica") -> 0
A36: Alta | B36: =COUNTIF(Bugs!$F$2:$F$61,"Alta") -> 0
A37: Media | B37: =COUNTIF(Bugs!$F$2:$F$61,"Media") -> 0
A38: Baja | B38: =COUNTIF(Bugs!$F$2:$F$61,"Baja") -> 0
A39: Total de bugs registrados | B39: =COUNTA(Bugs!$B$2:$B$61) -> 0
A40: Bugs confirmados (reproducidos 2 veces o más) | B40: =COUNTIF(Bugs!$H$2:$H$61,"Confirmado") -> 0
A42: Bugs por usuario
A43: standard_user | B43: =COUNTIF(Bugs!$D$2:$D$61,A43) -> 0
A44: locked_out_user | B44: =COUNTIF(Bugs!$D$2:$D$61,A44) -> 0
A45: problem_user | B45: =COUNTIF(Bugs!$D$2:$D$61,A45) -> 0
A46: performance_glitch_user | B46: =COUNTIF(Bugs!$D$2:$D$61,A46) -> 0
...

Sheet Casos de prueba
A1: ID | B1: Módulo | C1: Requisito | D1: Título | E1: Usuario | F1: Precondiciones | G1: Pasos | H1: Datos de prueba | I1: Resultado esperado | J1: Prioridad | K1: Tipo | L1: Técnica de diseño | M1: Resultado obtenido | N1: Estado | O1: ID Bug | P1: Fecha de ejecución | Q1: Navegador | R1: Notas
A2: TC-001 | B2: Login | C2: REQ-01 | D2: Inicio de sesión exitoso con usuario estándar | E2: standard_user | F2: Página de login abierta en ventana de incógnito | G2: 1. Escribir el usuario. 2. Escribir la contraseña. 3. Hacer clic en "Login". | H2: Usuario: standard_user Contraseña: válida | I2: Se abre la página de productos (/inventory.html) con el título "Products". | J2: Alta | K2: Funcional | L2: Partición de equivalencia (válida) | N2: No ejecutado
A3: TC-002 | B3: Login | C3: REQ-02 | D3: Inicio de sesión con contraseña incorrecta | E3: standard_user | F3: Página de login abierta en ventana de incógnito | G3: 1. Escribir el usuario. 2. Escribir una contraseña incorrecta. 3. Hacer clic en "Login". | H3: Usuario: standard_user Contraseña: clave123 | I3: No se inicia sesión. Se muestra: "Epic sadface: Username and password do not match any user in this service". | J3: Alta | K3: Negativa | L3: Partición de equivalencia (inválida) | N3: No ejecutado
A4: TC-003 | B4: Login | C4: REQ-02 | D4: Inicio de sesión con usuario inexistente | E4: usuario_falso | F4: Página de login abierta en ventana de incógnito | G4: 1. Escribir un usuario que no existe. 2. Escribir la contraseña. 3. Hacer clic en "Login". | H4: Usuario: usuario_falso Contraseña: válida | I4: No se inicia sesión. Se muestra: "Epic sadface: Username and password do not match any user in this service". | J4: Media | K4: Negativa | L4: Partición de equivalencia (inválida) | N4: No ejecutado
A5: TC-004 | B5: Login | C5: REQ-02 | D5: Inicio de sesión con el usuario vacío | E5: (vacío) | F5: Página de login abierta en ventana de incógnito | G5: 1. Dejar vacío el campo de usuario. 2. Escribir la contraseña. 3. Hacer clic en "Login". | H5: Usuario: (vacío) Contraseña: válida | I5: No se inicia sesión. Se muestra: "Epic sadface: Username is required". | J5: Alta | K5: Negativa | L5: Valores límite (campo vacío) | N5: No ejecutado
A6: TC-005 | B6: Login | C6: REQ-02 | D6: Inicio de sesión con la contraseña vacía | E6: standard_user | F6: Página de login abierta en ventana de incógnito | G6: 1. Escribir el usuario. 2. Dejar vacía la contraseña. 3. Hacer clic en "Login". | H6: Usuario: standard_user Contraseña: (vacía) | I6: No se inicia sesión. Se muestra: "Epic sadface: Password is required". | J6: Alta | K6: Negativa | L6: Valores límite (campo vacío) | N6: No ejecutado
A7: TC-006 | B7: Login | C7: REQ-02 | D7: Inicio de sesión con ambos campos vacíos | E7: (vacío) | F7: Página de login abierta en ventana de incógnito | G7: 1. Dejar ambos campos vacíos. 2. Hacer clic en "Login". | H7: Usuario: (vacío) Contraseña: (vacía) | I7: No se inicia sesión. Se muestra: "Epic sadface: Username is required". | J7: Media | K7: Negativa | L7: Valores límite (campo vacío) | N7: No ejecutado
A8: TC-007 | B8: Login | C8: REQ-03 | D8: Inicio de sesión con usuario bloqueado | E8: locked_out_user | F8: Página de login abierta en ventana de incógnito | G8: 1. Escribir el usuario bloqueado. 2. Escribir la contraseña. 3. Hacer clic en "Login". | H8: Usuario: locked_out_user Contraseña: válida | I8: No se inicia sesión. Se muestra: "Epic sadface: Sorry, this user has been locked out.". | J8: Alta | K8: Negativa | L8: Partición de equivalencia (bloqueado) | N8: No ejecutado
A9: TC-008 | B9: Login | C9: REQ-04 | D9: La contraseña se oculta al escribirla | E9: — | F9: Página de login abierta en ventana de incógnito | G9: 1. Escribir un texto en el campo de contraseña. 2. Observar el campo. | H9: Contraseña: prueba123 | I9: Los caracteres se ven como puntos, no como texto legible. | J9: Media | K9: Seguridad / Interfaz | L9: Verificación de interfaz | N9: No ejecutado
A10: TC-009 | B10: Login | C10: REQ-02 | D10: Cerrar el mensaje de error | E10: (vacío) | F10: Mensaje de error visible (ejecutar antes TC-004) | G10: 1. Hacer clic en la "X" del mensaje de error. | H10: — | I10: El mensaje desaparece y los campos dejan de estar marcados como error. | J10: Baja | K10: Interfaz | L10: Transición de estados | N10: No ejecutado
A11: TC-010 | B11: Login | C11: REQ-04 | D11: Entrar a una página interna sin iniciar sesión | E11: — | F11: Ventana de incógnito nueva, sin sesión iniciada | G11: 1. Escribir en la barra de direcciones: https://www.saucedemo.com/inventory.html 2. Presionar Enter. | H11: URL: /inventory.html | I11: No se muestran los productos. Aparece el login con el mensaje: "Epic sadface: You can only access '/inventory.html' when you are logged in.". | J11: Alta | K11: Seguridad | L11: Prueba negativa | N11: No ejecutado
A12: TC-011 | B12: Login | C12: REQ-01 | D12: Inicio de sesión con la tecla Enter | E12: standard_user | F12: Página de login abierta en ventana de incógnito | G12: 1. Escribir el usuario. 2. Escribir la contraseña. 3. Presionar Enter sin hacer clic en "Login". | H12: Usuario: standard_user Contraseña: válida | I12: Se inicia sesión igual que con el botón "Login". | J12: Baja | K12: Usabilidad | L12: Prueba funcional | N12: No ejecutado
A13: TC-012 | B13: Catálogo | C13: REQ-05 | D13: El catálogo muestra los 6 productos completos | E13: standard_user | F13: Sesión iniciada con standard_user; carrito vacío | G13: 1. Observar la página de productos. 2. Revisar cada producto. | H13: Sauce Labs Backpack $29.99 Sauce Labs Bike Light $9.99 Sauce Labs Bolt T-Shirt $15.99 Sauce Labs Fleece Jacket $49.99 Sauce Labs Onesie $7.99 Test.allTheThings() T-Shirt (Red) $15.99 | I13: Se ven 6 productos. Cada uno tiene imagen, nombre, descripción, precio y botón "Add to cart". Nombres y precios coinciden con los datos de prueba. | J13: Alta | K13: Funcional / Interfaz | L13: Verificación contra oráculo | N13: No ejecutado
... A51: TC-050 | B51: Flujo completo | C51: REQ-17 | D51: Flujo completo de compra en Firefox | E51: standard_user | F51: Firefox en ventana privada | G51: 1. Repetir en Firefox los casos TC-001, TC-017, TC-027, TC-033 y TC-035. 2. Comparar con los resultados en Chrome. | H51: First Name: Ana Last Name: Gómez Zip/Postal Code: 110111 | I51: El comportamiento es igual al de Chrome. | J51: Baja | K51: Compatibilidad | L51: Prueba funcional | N51: No ejecutado

Sheet Requisitos
A1: ID | B1: Requisito | C1: Fuente | D1: Módulo | E1: Casos que lo cubren | F1: N.º de casos | G1: Casos ejecutados | H1: Casos fallidos | I1: Cobertura | J1: Resultado
A2: REQ-01 | B2: El usuario con credenciales válidas accede al catálogo. | C2: Observado | D2: Login | E2: TC-001, TC-011 | F2: =COUNTIF('Casos de prueba'!$C$2:$C$500,A2) -> 2 | G2: =COUNTIFS('Casos de prueba'!$C$2:$C$500,A2,'Casos de prueba'!$N$2:$N$500,"Aprobado")+COUNTIFS('Casos de prueba'!$C$2:$C$500,A2,'Casos de prueba'!$N$2:$N$500,"Fallido") -> 0 | H2: =COUNTIFS('Casos de prueba'!$C$2:$C$500,A2,'Casos de prueba'!$N$2:$N$500,"Fallido") -> 0 | I2: =IF(G2>0,"Cubierto","Pendiente") -> Pendiente | J2: =IF(G2=0,"Sin ejecutar",IF(H2>0,"Con fallas","OK")) -> Sin ejecutar
A3: REQ-02 | B3: El sistema muestra un mensaje claro cuando faltan datos o las credenciales son incorrectas. | C3: Observado | D3: Login | E3: TC-002, TC-003, TC-004, TC-005, TC-006, TC-009 | F3: =COUNTIF('Casos de prueba'!$C$2:$C$500,A3) -> 6 | G3: =COUNTIFS('Casos de prueba'!$C$2:$C$500,A3,'Casos de prueba'!$N$2:$N$500,"Aprobado")+COUNTIFS('Casos de prueba'!$C$2:$C$500,A3,'Casos de prueba'!$N$2:$N$500,"Fallido") -> 0 | H3: =COUNTIFS('Casos de prueba'!$C$2:$C$500,A3,'Casos de prueba'!$N$2:$N$500,"Fallido") -> 0 | I3: =IF(G3>0,"Cubierto","Pendiente") -> Pendiente | J3: =IF(G3=0,"Sin ejecutar",IF(H3>0,"Con fallas","OK")) -> Sin ejecutar
A4: REQ-03 | B4: Un usuario bloqueado no puede ingresar. | C4: Observado | D4: Login | E4: TC-007 | F4: =COUNTIF('Casos de prueba'!$C$2:$C$500,A4) -> 1 | G4: =COUNTIFS('Casos de prueba'!$C$2:$C$500,A4,'Casos de prueba'!$N$2:$N$500,"Aprobado")+COUNTIFS('Casos de prueba'!$C$2:$C$500,A4,'Casos de prueba'!$N$2:$N$500,"Fallido") -> 0 | H4: =COUNTIFS('Casos de prueba'!$C$2:$C$500,A4,'Casos de prueba'!$N$2:$N$500,"Fallido") -> 0 | I4: =IF(G4>0,"Cubierto","Pendiente") -> Pendiente | J4: =IF(G4=0,"Sin ejecutar",IF(H4>0,"Con fallas","OK")) -> Sin ejecutar
A5: REQ-04 | B5: Seguridad básica: la contraseña se oculta, las páginas internas exigen sesión y el logout cierra la sesión. | C5: Observado | D5: Login / Menú | E5: TC-008, TC-010, TC-037 | F5: =COUNTIF('Casos de prueba'!$C$2:$C$500,A5) -> 3 | G5: =COUNTIFS('Casos de prueba'!$C$2:$C$500,A5,'Casos de prueba'!$N$2:$N$500,"Aprobado")+COUNTIFS('Casos de prueba'!$C$2:$C$500,A5,'Casos de prueba'!$N$2:$N$500,"Fallido") -> 0 | H5: =COUNTIFS('Casos de prueba'!$C$2:$C$500,A5,'Casos de prueba'!$N$2:$N$500,"Fallido") -> 0 | I5: =IF(G5>0,"Cubierto","Pendiente") -> Pendiente | J5: =IF(G5=0,"Sin ejecutar",IF(H5>0,"Con fallas","OK")) -> Sin ejecutar
A6: REQ-05 | B6: El catálogo muestra todos los productos con imagen, nombre, descripción y precio correctos. | C6: Observado | D6: Catálogo | E6: TC-012 | F6: =COUNTIF('Casos de prueba'!$C$2:$C$500,A6) -> 1 | G6: =COUNTIFS('Casos de prueba'!$C$2:$C$500,A6,'Casos de prueba'!$N$2:$N$500,"Aprobado")+COUNTIFS('Casos de prueba'!$C$2:$C$500,A6,'Casos de prueba'!$N$2:$N$500,"Fallido") -> 0 | H6: =COUNTIFS('Casos de prueba'!$C$2:$C$500,A6,'Casos de prueba'!$N$2:$N$500,"Fallido") -> 0 | I6: =IF(G6>0,"Cubierto","Pendiente") -> Pendiente | J6: =IF(G6=0,"Sin ejecutar",IF(H6>0,"Con fallas","OK")) -> Sin ejecutar
A7: REQ-06 | B7: Los productos se pueden ordenar por nombre y por precio, en ambos sentidos. | C7: Observado | D7: Catálogo | E7: TC-013, TC-014, TC-015, TC-016 | F7: =COUNTIF('Casos de prueba'!$C$2:$C$500,A7) -> 4 | G7: =COUNTIFS('Casos de prueba'!$C$2:$C$500,A7,'Casos de prueba'!$N$2:$N$500,"Aprobado")+COUNTIFS('Casos de prueba'!$C$2:$C$500,A7,'Casos de prueba'!$N$2:$N$500,"Fallido") -> 0 | H7: =COUNTIFS('Casos de prueba'!$C$2:$C$500,A7,'Casos de prueba'!$N$2:$N$500,"Fallido") -> 0 | I7: =IF(G7>0,"Cubierto","Pendiente") -> Pendiente | J7: =IF(G7=0,"Sin ejecutar",IF(H7>0,"Con fallas","OK")) -> Sin ejecutar
A8: REQ-07 | B8: El usuario puede agregar y quitar productos, y el contador del carrito se actualiza. | C8: Observado | D8: Catálogo / Detalle / Carrito | E8: TC-017, TC-018, TC-019, TC-021, TC-023, TC-024, TC-025 | F8: =COUNTIF('Casos de prueba'!$C$2:$C$500,A8) -> 7 | G8: =COUNTIFS('Casos de prueba'!$C$2:$C$500,A8,'Casos de prueba'!$N$2:$N$500,"Aprobado")+COUNTIFS('Casos de prueba'!$C$2:$C$500,A8,'Casos de prueba'!$N$2:$N$500,"Fallido") -> 0 | H8: =COUNTIFS('Casos de prueba'!$C$2:$C$500,A8,'Casos de prueba'!$N$2:$N$500,"Fallido") -> 0 | I8: =IF(G8>0,"Cubierto","Pendiente") -> Pendiente | J8: =IF(G8=0,"Sin ejecutar",IF(H8>0,"Con fallas","OK")) -> Sin ejecutar
A9: REQ-08 | B9: El detalle de producto muestra la misma información que el catálogo y permite volver. | C9: Observado | D9: Detalle | E9: TC-020, TC-022 | F9: =COUNTIF('Casos de prueba'!$C$2:$C$500,A9) -> 2 | G9: =COUNTIFS('Casos de prueba'!$C$2:$C$500,A9,'Casos de prueba'!$N$2:$N$500,"Aprobado")+COUNTIFS('Casos de prueba'!$C$2:$C$500,A9,'Casos de prueba'!$N$2:$N$500,"Fallido") -> 0 | H9: =COUNTIFS('Casos de prueba'!$C$2:$C$500,A9,'Casos de prueba'!$N$2:$N$500,"Fallido") -> 0 | I9: =IF(G9>0,"Cubierto","Pendiente") -> Pendiente | J9: =IF(G9=0,"Sin ejecutar",IF(H9>0,"Con fallas","OK")) -> Sin ejecutar
A10: REQ-09 | B10: Nombre, apellido y código postal son obligatorios en el checkout. | C10: Observado | D10: Checkout | E10: TC-027, TC-028, TC-029, TC-030 | F10: =COUNTIF('Casos de prueba'!$C$2:$C$500,A10) -> 4 | G10: =COUNTIFS('Casos de prueba'!$C$2:$C$500,A10,'Casos de prueba'!$N$2:$N$500,"Aprobado")+COUNTIFS('Casos de prueba'!$C$2:$C$500,A10,'Casos de prueba'!$N$2:$N$500,"Fallido") -> 0 | H10: =COUNTIFS('Casos de prueba'!$C$2:$C$500,A10,'Casos de prueba'!$N$2:$N$500,"Fallido") -> 0 | I10: =IF(G10>0,"Cubierto","Pendiente") -> Pendiente | J10: =IF(G10=0,"Sin ejecutar",IF(H10>0,"Con fallas","OK")) -> Sin ejecutar
A11: REQ-10 | B11: Los datos de envío deben tener un formato válido (no solo espacios; código postal válido). | C11: Inferido | D11: Checkout | E11: TC-031, TC-032 | F11: =COUNTIF('Casos de prueba'!$C$2:$C$500,A11) -> 2 | G11: =COUNTIFS('Casos de prueba'!$C$2:$C$500,A11,'Casos de prueba'!$N$2:$N$500,"Aprobado")+COUNTIFS('Casos de prueba'!$C$2:$C$500,A11,'Casos de prueba'!$N$2:$N$500,"Fallido") -> 0 | H11: =COUNTIFS('Casos de prueba'!$C$2:$C$500,A11,'Casos de prueba'!$N$2:$N$500,"Fallido") -> 0 | I11: =IF(G11>0,"Cubierto","Pendiente") -> Pendiente | J11: =IF(G11=0,"Sin ejecutar",IF(H11>0,"Con fallas","OK")) -> Sin ejecutar
A12: REQ-11 | B12: El resumen calcula bien subtotal, impuesto y total. | C12: Observado | D12: Checkout | E12: TC-033 | F12: =COUNTIF('Casos de prueba'!$C$2:$C$500,A12) -> 1 | G12: =COUNTIFS('Casos de prueba'!$C$2:$C$500,A12,'Casos de prueba'!$N$2:$N$500,"Aprobado")+COUNTIFS('Casos de prueba'!$C$2:$C$500,A12,'Casos de prueba'!$N$2:$N$500,"Fallido") -> 0 | H12: =COUNTIFS('Casos de prueba'!$C$2:$C$500,A12,'Casos de prueba'!$N$2:$N$500,"Fallido") -> 0 | I12: =IF(G12>0,"Cubierto","Pendiente") -> Pendiente | J12: =IF(G12=0,"Sin ejecutar",IF(H12>0,"Con fallas","OK")) -> Sin ejecutar
A13: REQ-12 | B13: No se puede comprar con el carrito vacío. | C13: Inferido | D13: Checkout | E13: TC-026 | F13: =COUNTIF('Casos de prueba'!$C$2:$C$500,A13) -> 1 | G13: =COUNTIFS('Casos de prueba'!$C$2:$C$500,A13,'Casos de prueba'!$N$2:$N$500,"Aprobado")+COUNTIFS('Casos de prueba'!$C$2:$C$500,A13,'Casos de prueba'!$N$2:$N$500,"Fallido") -> 0 | H13: =COUNTIFS('Casos de prueba'!$C$2:$C$500,A13,'Casos de prueba'!$N$2:$N$500,"Fallido") -> 0 | I13: =IF(G13>0,"Cubierto","Pendiente") -> Pendiente | J13: =IF(G13=0,"Sin ejecutar",IF(H13>0,"Con fallas","OK")) -> Sin ejecutar
... A18: REQ-17 | B18: El flujo de compra funciona en Chrome, en Firefox y en vista móvil. | C18: Inferido | D18: Todos | E18: TC-049, TC-050 | F18: =COUNTIF('Casos de prueba'!$C$2:$C$500,A18) -> 2 | G18: =COUNTIFS('Casos de prueba'!$C$2:$C$500,A18,'Casos de prueba'!$N$2:$N$500,"Aprobado")+COUNTIFS('Casos de prueba'!$C$2:$C$500,A18,'Casos de prueba'!$N$2:$N$500,"Fallido") -> 0 | H18: =COUNTIFS('Casos de prueba'!$C$2:$C$500,A18,'Casos de prueba'!$N$2:$N$500,"Fallido") -> 0 | I18: =IF(G18>0,"Cubierto","Pendiente") -> Pendiente | J18: =IF(G18=0,"Sin ejecutar",IF(H18>0,"Con fallas","OK")) -> Sin ejecutar
A20: Fuente: "Observado" = comportamiento de standard_user tomado como correcto. "Inferido" = lo esperado en cualquier tienda en línea; en un equipo real se confirma con el dueño del producto.
A21: Si agregas un caso nuevo, escribe su ID en "Casos que lo cubren". Los conteos y la cobertura se calculan solos.

Sheet Bugs
A1: ID | B1: Título | C1: Módulo | D1: Usuario | E1: Caso relacionado | F1: Severidad | G1: Prioridad | H1: Estado | I1: Navegador | J1: Fecha | K1: Archivo del reporte | L1: Archivo de evidencia

Sheet Cómo usar
A1: Cómo usar este archivo
A3: HOJAS
A4: Resumen | B4: Métricas que se calculan solas: ejecución, aprobación, cobertura y bugs. No se escribe nada aquí.
A5: Casos de prueba | B5: Los 50 casos diseñados. Columnas blancas: el diseño del caso. Columnas amarillas: lo que llenas al ejecutar.
A6: Requisitos | B6: Matriz de trazabilidad: qué casos cubren cada requisito y si ya se probó. Se actualiza sola.
A7: Bugs | B7: Registro de bugs, uno por fila. Cada bug también tiene su archivo BUG-XXX.md en la carpeta reportes-de-bugs.
A9: AL EJECUTAR UN CASO
A10: 1. Prepárate | B10: Abre una ventana de incógnito nueva para cada usuario. La contraseña de todos los usuarios aparece en la página de login de SauceDemo.
A11: 2. Sigue los pasos | B11: Haz exactamente lo que dicen las columnas "Pasos" y "Datos de prueba".
A12: 3. Compara | B12: Compara lo que pasó con el "Resultado esperado".
A13: 4. Registra | B13: Llena las columnas amarillas: Resultado obtenido (qué pasó en realidad), Estado (elige de la lista), Fecha de ejecución y Navegador.
A14: 5. Si falla | B14: Estado = Fallido. Toma la captura, reproduce el fallo una vez más, registra el bug en la hoja "Bugs", crea su archivo BUG-XXX.md y escribe el ID del bug en la columna "ID Bug" del caso.
A16: ESTADOS
A17: Aprobado | B17: El resultado obtenido es igual al esperado.
A18: Fallido | B18: El resultado obtenido es distinto del esperado. Siempre lleva un bug asociado.
A19: Bloqueado | B19: No se pudo ejecutar porque otro fallo lo impide. Explica cuál en "Notas".
A20: No ejecutado | B20: Todavía no se ha probado. Es el valor inicial.
A22: SEVERIDAD DE BUGS
A23: Crítica | B23: Bloquea una función principal y no hay forma de evitarlo.
A24: Alta | B24: Una función importante falla o muestra datos incorrectos.
A25: Media | B25: Falla una función secundaria o un problema de interfaz confunde.
A26: Baja | B26: Problema cosmético que no afecta el uso.
A28: EJEMPLO DE FILA EN "BUGS"
A29: (solo muestra el formato; no es un hallazgo real) | B29: ID: BUG-001 · Título: [Carrito] standard_user: el contador no se actualiza al quitar un producto · Módulo: Carrito · Usuario: standard_user · Caso relacionado: TC-024 · Severidad: Media · Prioridad: Media · Estado: Confirmado · Navegador: Chrome · Fecha: 05/10/2026 · Archivo del reporte: BUG-001.md · Archivo de evidencia: BUG-001_carrito_contador.png
A31: ACTUALIZAR GITHUB
A32: Excel | B32: Sube este archivo con el mismo nombre (Add file › Upload files) y reemplaza al anterior.
A33: CSV para vista rápida | B33: En Excel: abre la hoja "Casos de prueba", Archivo › Guardar como › "CSV UTF-8 (delimitado por comas)", nómbralo casos-de-prueba.csv y súbelo. En Google Sheets: Archivo › Descargar › Valores separados por comas (hoja actual).
A35: COLORES
A36: Encabezado azul oscuro | B36: Diseño del caso. Se ajusta en las fases 1 y 2.
A37: Encabezado dorado y celdas amarillas | B37: Lo que llenas al ejecutar.
